Workbook

Sheet DATOS PARAMETROS
A1: PARAMETROS
A2: LLENAR CELDAS VERDES
A3: % | B3: DECIMAL | C3: CONCEPTO | F3: VALORES % | I3: VALORES DECIMALES
B4: 40120.2 | C4: VALOR UF | E4: AFP | F4: COTIZACION | G4: SIS | H4: TOTAL | I4: COTIZACION
B5: 69889 | C5: VALOR UTM | E5: AFP CAPITAL | F5: 0.1144 | G5: 0.0162 | H5: =+F5+G5 -> 0.1306 | I5: 11.44
B6: 539000 | C6: SUELDO MINIMO | E6: AFP CUPRUM | F6: 0.1144 | G6: 0.0162 | H6: =+F6+G6 -> 0.1306 | I6: 11.44
B7: 90 | C7: TOPE IMPONIBLE AFP | E7: AFP HABITAT | F7: 0.1127 | G7: 0.0162 | H7: =+F7+G7 -> 0.1289 | I7: 11.27
B8: 135.2 | C8: TOPE IMPONIBLE SEG.CES. | E8: AFP PLANVITAL | F8: 0.1116 | G8: 0.0162 | H8: =+F8+G8 -> 0.1278 | I8: 11.16
A9: 0.07 | B9: 7 | C9: FONASA | E9: AFP PROVIDA | F9: 0.1145 | G9: 0.0162 | H9: =+F9+G9 -> 0.1307 | I9: 11.45
A10: 0.006 | B10: 0.6 | C10: AFC TRABAJADOR | E10: AFP MODELO | F10: 0.1058 | G10: 0.0162 | H10: =+F10+G10 -> 0.122 | I10: 10.58
A11: 0.024 | B11: 2.4 | C11: AFC EMPRESA | E11: AFP UNO | F11: 0.1046 | G11: 0.0162 | H11: =+F11+G11 -> 0.1208 | I11: 10.46
B12: =4.75*B6/12 -> 213354.17 | C12: TOPE GRATIFICACION | E12: SIN AFP
B13: =ROUND(B12/0.25,0) -> 853417 | C13: TOPE SUELDO GRATIFICACION | E13: SALUD FONASA | F13: 0.07 | G13: 0 | H13: 0 | I13: 7
L24: PLAZO FIJO
L25: INDEFINIDO
L27: SI
L28: NO
L29: MENSUAL
L30: ANUAL
L33: FONASA | M33: 0.07
L34: ISAPRE BANMEDICA
L35: ISAPRE CRUZ BLANCA
L36: ISAPRE NUEVA MAS VIDA
L37: ISAPRE COLMENA
L38: ISAPRE CONSALUD
L39: ISAPRE VIDA TRES

Sheet CALCULO SUELDO LIQ. A BRUTO
C3: CALCULO SUELDO LIQUIDO A BRUTO
C4: DEL SUELDO LIQUIDO LLEGARA AL SUELDO BASE
C5: SUELDO LIQUIDO DESEADO | D5: 850000
E6: =+'DATOS PARAMETROS'!B5 -> 69889 | F6: UF | G6: =+'DATOS PARAMETROS'!B4 -> 40120.2
C7: SUELDO BASE | G7: =+J26 -> 552459.41 | J7: CALCULOS COMPLEMENTARIOS
J8: =+'DATOS PARAMETROS'!B13 -> 853417 | K8: TOPE SUELDO GRATIFICACION
C9: OTROS BONOS IMPONIBLES | J9: =+'DATOS PARAMETROS'!B12 -> 213354.17 | K9: TOPE GRATIFICACION
C10: GRATIFICACION LEGAL | D10: MENSUAL | E10: =IF(C10="MENSUAL",0.25,"") | F10: =IF(D10="MENSUAL",0.25,"") -> 0.25 | G10: =IF(F10=0.25,IF((G7+G9)*25%>(4.75*'DATOS PARAMETROS'!B6/12),4.75*'DATOS PARAMETROS'!B6/12,(G7+G9)*0.25),"0") -> 138114.85 | J10: =+D10 -> MENSUAL | K10: TIPO GRATIFICACION
J11: =(J22*0.25)/1.25 -> 138114.85 | K11: GRATIFICACION CALCULADA
C12: TOTAL HABERES IMPONIBLES | G12: =+G7+G10+G9 -> 690574.27 | J12: =+'DATOS PARAMETROS'!B4*'DATOS PARAMETROS'!B7 -> 3610818 | K12: TOPE IMPONIBLE AFP
J13: =+'DATOS PARAMETROS'!B4*'DATOS PARAMETROS'!B8 -> 5424251 | K13: TOPE IMPONIBLE AFC
C14: COLACION | G14: 140000 | J14: =((F22+F23)/100)*J12 -> 630448.82 | K14: COTIZACIONES SOBRE TOPE | L14: ((F22+F23)/100)*J12
C15: MOVILIZACION | G15: 140000 | J15: =+J20+J14 -> 1200448.8 | K15: ESTIMACION RENTA SOBRE TOPE
C16: OTROS HABERES NO IMPONIBLES | J16: =IF(J15>J12,"SI","NO") -> NO | K16: OPCION RENTA SOBRE TOPE
C17: OTROS HABERES NO IMPONIBLES | J17: =+D5 -> 850000 | K17: SUELDO LIQUIDO DESEADO
J18: =G19 -> 280000 | K18: HABERES NO IMPONIBLES
C19: TOTAL HABERES NO IMPONIBLES | G19: =SUM(G14:G17) -> 280000 | J19: =+G9 -> 0 | K19: HABERES IMPONIBLES | M19: TABLA DE IMPUESTO UNICO A LOS TRABAJADORES SUELDO LIQUIDO A BRUTO
C20: =IF(AND(C23="FONASA",D26>0),"ATENCION NO PUEDE TENER PLAN ISAPRE CON FONASA","") | J20: =+J17-J18 -> 570000 | K20: SUBTOTAL | M20: RENTA | N20: IMPTO | O20: UTM
C21: TOTAL TRIBUTABLE | G21: =+J27 -> 570000 | J21: =100-(F22+F23+F24) -> 82.54 | K21: INCREMENTO COTIZACIONES | M21: =+G21 -> 570000 | N21: =IF(AND($M$21>=N24,$M$21<=O24),R24,IF(AND($M$21>N25,$M$21<=O25),R25,IF(AND($M$21>N26,M21<=O26),R26,IF(AND(M21>N27,M21<=O27),R27,IF(IF(M21>N28,M21<=O28),R28,IF(AND(M21>N29,M21<=O29),R29,IF(AND(M21>N30,M21<=O30),R30,R31))))))) -> 0 | O21: =+E6 -> 69889
C22: AFP UNO | D22: COTIZACION LEGAL | F22: =VLOOKUP(C22,'DATOS PARAMETROS'!E5:I11,5,0) -> 10.46 | G22: =IF(G12<=J12,(F22/100)*-G12,(F22/100)*-J12) -> -72234.068 | J22: =IF((J20*100)/J21<=J12,(J20*100)/J21,(J12*100)/J21) -> 690574.27 | K22: SUB TOTAL IMPONIBLE
C23: FONASA | D23: COTIZACION LEGAL | F23: 7 | G23: =IF(G12<=J12,(F23/100)*-G12,(F23/100)*-J12) -> -48340.199 | J23: =+D26*'DATOS PARAMETROS'!B4 -> 0 | K23: PLAN DE ISAPRE X UF | M23: RENTA x FACTOR | N23: DESDE | O23: HASTA | P23: FACTOR | Q23: CANTIDAD A REBAJAR | R23: CALCULO
C24: AFC TRABAJADOR | E24: PLAZO FIJO | F24: =IF(E24="INDEFINIDO",0.6,"0") -> 0 | G24: =IF(G12<=J13,(F24/100)*-G12,(F24/100)*-J13) -> 0 | J24: =+G23*-1 -> 48340.199 | K24: VALOR SALUD | M24: =+M21*P24 -> 0 | N24: 0 | O24: =13.5*O21 -> 943501.5 | P24: 0 | Q24: 0 | R24: =(M21*P24)-Q24 -> 0
C25: ADICIONAL ISAPRE E IMPTO. UNICO CARGO EMPRESA CARGO TRABAJADOR | J25: =IF(D10="MENSUAL",IF(J11<=J9,J11,J9),0) -> 138114.85 | K25: GRATIFICACION | M25: =+(M21*P25)-Q25 -> -14940.06 | N25: =+O24 -> 943501.5 | O25: =30*O21 -> 2096670 | P25: 0.04 | Q25: =0.54*O21 -> 37740.06 | R25: =IF(M25<=0,"0",M25) -> 0
C26: VALOR EN UF PLAN ISAPRE | F26: ADICIONAL ISAPRE | G26: =IF(OR(C35=1,C35=2),J29,0) -> 0 | J26: =IF(J16="SI",J20+J14-J19-J25,(J22-J25-J19)) -> 552459.41 | K26: SUELDO BASE | M26: =+(M21*P26)-Q26 -> -76006.86 | N26: =+O25 -> 2096670 | O26: =50*O21 -> 3494450 | P26: 0.08 | Q26: =1.74*O21 -> 121606.86 | R26: =IF(M26<=0,"0",M26) -> 0
C27: IMPUESTO UNICO TRABAJADOR | G27: =IF(OR(OR(C35=1,C35=2)),J30,0) -> 0 | J27: =+G12+G22+G23+G24+J29+J28 -> 570000 | K27: SUELDO TRIBUTABLE | M27: =+(M21*P27)-Q27 -> -236851.61 | N27: =+O26 -> 3494450 | O27: =70*O21 -> 4892230 | P27: 0.135 | Q27: =4.49*O21 -> 313801.61 | R27: =IF(M27<=0,"0",M27) -> 0
C28: TOTAL DESCUENTOS LEGALES | G28: =SUM(G22:G23)+G24+G26+G27 -> -120574.27 | J28: =IF(IF(D26>0,(J23-(('DATOS PARAMETROS'!B7*7%)*G6)),0)<0,0,IF(D26>0,(J23-(('DATOS PARAMETROS'!B7*7%)*G6)),0)) -> 0 | K28: DIFERENCIA CON TOPE IMPONIBLE | M28: =+(M21*P28)-Q28 -> -647463.46 | N28: =+O27 -> 4892230 | O28: =90*O21 -> 6290010 | P28: 0.23 | Q28: =11.14*O21 -> 778563.46 | R28: =IF(M28<=0,"0",M28) -> 0
C29: DEVOLUCION NO IMPONIBLE POR ADICIONAL ISAPRE E IMPTO UNICO Y AFC | G29: =IF(C35=1,(J29+J30)*-1,0) -> 0 | J29: =IF(J23>J24,J23-J24,0)*-1 -> 0 | K29: ADICIONAL ISAPRE | M29: =+(M21*P29)-Q29 -> -1070744.2 | N29: =+O28 -> 6290010 | O29: =120*O21 -> 8386680 | P29: 0.304 | Q29: =17.8*O21 -> 1244024.2 | R29: =IF(M29<=0,"0",M29) -> 0
C30: SUELDO LIQUIDO | G30: =+G12+G19+G22+G23+G24+G26+G27+G29 -> 850000 | J30: =+N21*-1 -> 0 | K30: IMPUESTO UNICO TRABAJADORES | M30: =+(M21*P30)-Q30 -> -1430311.5 | N30: =+O29 -> 8386680 | O30: =150*O21 -> 10483350 | P30: 0.35 | Q30: =23.32*O21 -> 1629811.5 | R30: =IF(M30<=0,"0",M30) -> 0
C31: =IF(C35=2,"CARGO A CUENTA DEL TRABAJADOR","DEVOLUCION AFC") -> CARGO A CUENTA DEL TRABAJADOR | G31: =+J32 -> 0 | J31: =+G24 -> 0 | K31: AFC COSTO TRABAJADOR | M31: =+(M21*P31)-Q31 -> -1925979 | N31: =+O30 -> 10483350 | O31: 1e+09 | P31: 0.4 | Q31: =30.82*O21 -> 2153979 | R31: =IF(M31<=0,"0",M31) -> 0
J32: =+D5-G30 -> 0 | K32: DIFERENCIA
C33: SUELDO LIQUIDO FINAL | G33: =+G30+G31 -> 850000 | J33: =G12*'DATOS PARAMETROS'!G5 -> 11187.303 | K33: SIS
G34: =+F31+G33 -> 850000 | J34: =G12*3% -> 20717.228 | K34: AFC COSTO EMPRESA
C35: 2
J36: =G12*3.48% -> 24031.984 | K36: SEGURO
J37: =G12*1% -> 6905.7427 | K37: REFORMA
D38: COSTO TOTAL X TRABAJADOR
D40: SUELDO LIQUIDO | F40: =G33 -> 850000
D42: TRABAJADOR | E42: SALUD | F42: =-G23 -> 48340.199
E43: AFP | F43: =-G22 -> 72234.068
E44: AFC | F44: =-G24 -> 0
...

Sheet CALCULO SUELDO BRUTO A LIQUIDO
C4: CALCULO SUELDO BRUTO A LIQUIDO
C5: DEL SUELDO BRUTO LLEGARA AL SUELDO LIQUIDO
D6: UTM | E6: =+'DATOS PARAMETROS'!B5 -> 69889 | F6: UF | G6: =+'DATOS PARAMETROS'!B4 -> 40120.2
C8: SUELDO BASE | G8: 539000 | J8: CALCULOS COMPLEMENTARIOS
J9: =+'DATOS PARAMETROS'!B13 -> 853417 | K9: TOPE SUELDO GRATIFICACION
C10: OTROS BONOS IMPONIBLES | J10: =+'DATOS PARAMETROS'!B12 -> 213354.17 | K10: TOPE GRATIFICACION
C11: GRATIFICACION LEGAL | D11: MENSUAL | E11: =IF(C11="MENSUAL",0.25,"") | F11: =IF(D11="MENSUAL",0.25,"") -> 0.25 | G11: =IF(F11=0.25,IF((G8+G10)*25%>(4.75*'DATOS PARAMETROS'!B6/12),4.75*'DATOS PARAMETROS'!B6/12,(G8+G10)*0.25),"0") -> 134750 | J11: =+D11 -> MENSUAL | K11: TIPO GRATIFICACION
J12: =(J23*0.25)/1.25 -> 128165.91 | K12: GRATIFICACION CALCULADA
C13: TOTAL HABERES IMPONIBLES | G13: =+G8+G11+G10 -> 673750 | J13: =+'DATOS PARAMETROS'!B7*'DATOS PARAMETROS'!B4 -> 3610818 | K13: TOPE IMPONIBLE AFP
J14: =+'DATOS PARAMETROS'!B8*'DATOS PARAMETROS'!B4 -> 5424251 | K14: TOPE IMPONIBLE AFC
C15: COLACION | G15: 75000 | J15: =((F23+F24)/100)*J13 -> 659696.45 | K15: COTIZACIONES SOBRE TOPE
C16: MOVILIZACION | G16: 75000 | J16: =+J21+J15 -> 1183446.4 | K16: ESTIMACION RENTA SOBRE TOPE
C17: OTROS HABERES NO IMPONIBLES | J17: =IF(J16>J13,"SI","NO") -> NO | K17: OPCION RENTA SOBRE TOPE
C18: OTROS HABERES NO IMPONIBLES | J18: =+G13 -> 673750 | K18: SUELDO LIQUIDO DESEADO
J19: =G20 -> 150000 | K19: HABERES NO IMPONIBLES
C20: TOTAL HABERES NO IMPONIBLES | G20: =SUM(G15:G18) -> 150000 | J20: =+G10 -> 0 | K20: HABERES IMPONIBLES | M20: TABLA DE IMPUESTO UNICO A LOS TRABAJADORES SUELDO LIQUIDO A BRUTO
C21: =IF(AND(C24="FONASA",D27>0),"ATENCION NO PUEDE TENER PLAN ISAPRE CON FONASA","") | J21: =+J18-J19 -> 523750 | K21: SUBTOTAL | M21: RENTA | N21: IMPTO | O21: UTM
C22: TOTAL TRIBUTABLE | G22: =+J28 -> 550655.88 | J22: =100-(F23+F24+F25) -> 81.73 | K22: INCREMENTO COTIZACIONES | M22: =+G22 -> 550655.88 | N22: =IF(AND($M$22>=N25,$M$22<=O25),R25,IF(AND($M$22>N26,$M$22<=O26),R26,IF(AND($M$22>N27,M22<=O27),R27,IF(AND(M22>N28,M22<=O28),R28,IF(IF(M22>N29,M22<=O29),R29,IF(AND(M22>N30,M22<=O30),R30,IF(AND(M22>N31,M22<=O31),R31,R32))))))) -> 0 | O22: =+E6 -> 69889
C23: AFP HABITAT | D23: COTIZACION LEGAL | F23: =VLOOKUP(C23,'DATOS PARAMETROS'!E5:I11,5,0) -> 11.27 | G23: =IF(G13<=J13,(F23/100)*-G13,(F23/100)*-J13) -> -75931.625 | J23: =IF((J21*100)/J22<=J13,(J21*100)/J22,(J13*100)/J22) -> 640829.56 | K23: SUB TOTAL IMPONIBLE
C24: FONASA | D24: COTIZACION LEGAL | F24: 7 | G24: =IF(G13<=J13,(F24/100)*-G13,(F24/100)*-J13) -> -47162.5 | J24: =+D27*'DATOS PARAMETROS'!B4 -> 0 | K24: PLAN DE ISAPRE X UF | M24: RENTA x FACTOR | N24: DESDE | O24: HASTA | P24: FACTOR | Q24: CANTIDAD A REBAJAR | R24: CALCULO
C25: AFC TRABAJADOR | D25: PLAZO FIJO | F25: =IF(D25="INDEFINIDO",0.6,"0") -> 0 | G25: =IF(G13<=J14,(F25/100)*-G13,(F25/100)*-J14) -> 0 | J25: =+G24*-1 -> 47162.5 | K25: VALOR SALUD | M25: =+M22*P25 -> 0 | N25: 0 | O25: =13.5*O22 -> 943501.5 | P25: 0 | Q25: 0 | R25: =(M22*P25)-Q25 -> 0
C26: ADICIONAL ISAPRE E IMPTO. UNICO CARGO EMPRESA CARGO TRABAJADOR | J26: =IF(D11="MENSUAL",IF(J12<=J10,J12,J10),0) -> 128165.91 | K26: GRATIFICACION | M26: =+(M22*P26)-Q26 -> -15713.825 | N26: =+O25 -> 943501.5 | O26: =30*O22 -> 2096670 | P26: 0.04 | Q26: =0.54*O22 -> 37740.06 | R26: =IF(M26<=0,"0",M26) -> 0
C27: VALOR EN UF PLAN ISAPRE | F27: ADICIONAL ISAPRE | G27: =IF(OR(C36=1,C36=2),J30,0) -> 0 | J27: =IF(J17="SI",J21+J15-J20-J26,(J23-J26-J20)) -> 512663.65 | K27: SUELDO BASE | M27: =+(M22*P27)-Q27 -> -77554.39 | N27: =+O26 -> 2096670 | O27: =50*O22 -> 3494450 | P27: 0.08 | Q27: =1.74*O22 -> 121606.86 | R27: =IF(M27<=0,"0",M27) -> 0
C28: IMPUESTO UNICO TRABAJADOR | G28: =IF(OR(OR(C36=1,C36=2)),J31,0) -> 0 | J28: =+G13+G23+G24+G25 -> 550655.88 | K28: SUELDO TRIBUTABLE | M28: =+(M22*P28)-Q28 -> -239463.07 | N28: =+O27 -> 3494450 | O28: =70*O22 -> 4892230 | P28: 0.135 | Q28: =4.49*O22 -> 313801.61 | R28: =IF(M28<=0,"0",M28) -> 0
C29: TOTAL DESCUENTOS LEGALES | G29: =SUM(G23:G24)+G25+G27+G28 -> -123094.12 | J29: =IF(IF(D27>0,(J24-(('DATOS PARAMETROS'!B7*7%)*G6)),0)<0,0,IF(D27>0,(J24-(('DATOS PARAMETROS'!B7*7%)*G6)),0)) -> 0 | K29: DIFERENCIA CON TOPE IMPONIBLE | M29: =+(M22*P29)-Q29 -> -651912.61 | N29: =+O28 -> 4892230 | O29: =90*O22 -> 6290010 | P29: 0.23 | Q29: =11.14*O22 -> 778563.46 | R29: =IF(M29<=0,"0",M29) -> 0
C30: DEVOLUCION NO IMPONIBLE POR ADICIONAL ISAPRE E IMPTO UNICO | G30: =IF(C36=1,(+G25+J30+J31)*-1,0) -> 0 | J30: =IF(J24>J25,J24-J25,0)*-1 -> 0 | K30: ADICIONAL ISAPRE | M30: =+(M22*P30)-Q30 -> -1076624.8 | N30: =+O29 -> 6290010 | O30: =120*O22 -> 8386680 | P30: 0.304 | Q30: =17.8*O22 -> 1244024.2 | R30: =IF(M30<=0,"0",M30) -> 0
C31: SUELDO LIQUIDO | G31: =+G13+G20+G23+G24+G25+G27+G28+G30 -> 700655.88 | J31: =+N22*-1 -> 0 | K31: IMPUESTO UNICO TRABAJADORES | M31: =+(M22*P31)-Q31 -> -1437081.9 | N31: =+O30 -> 8386680 | O31: =150*O22 -> 10483350 | P31: 0.35 | Q31: =23.32*O22 -> 1629811.5 | R31: =IF(M31<=0,"0",M31) -> 0
M32: =+(M22*P32)-Q32 -> -1933716.6 | N32: =+O31 -> 10483350 | O32: 1e+09 | P32: 0.4 | Q32: =30.82*O22 -> 2153979 | R32: =IF(M32<=0,"0",M32) -> 0
C34: SUELDO LIQUIDO FINAL | G34: =+G31+G32 -> 700655.88
C36: 2

Sheet COSTO TRABAJADOR
A2: COSTO TOTAL X TRABAJADOR
A4: SUELDO LIQUIDO | C4: ='CALCULO SUELDO LIQ. A BRUTO'!G33 -> 850000
A6: IMPOSICIONES | B6: SALUD | C6: =('CALCULO SUELDO LIQ. A BRUTO'!G23)*-1 -> 48340.199
B7: AFP | C7: =('CALCULO SUELDO LIQ. A BRUTO'!G22)*-1 -> 72234.068
B8: AFC | C8: =('CALCULO SUELDO LIQ. A BRUTO'!G24)*-1 -> 0
B9: IMPUESTO UNICO | C9: =('CALCULO SUELDO LIQ. A BRUTO'!G27)*-1 -> 0
A10: TOTAL IMPOSICIONES | C10: =SUM(C6:C9) -> 120574.27
A12: CARGO EMPLEADOR | B12: AFC | C12: ='CALCULO SUELDO LIQ. A BRUTO'!J34 -> 20717.228
B13: SIS | C13: ='CALCULO SUELDO LIQ. A BRUTO'!J33 -> 11187.303
B14: SEGURO | C14: ='CALCULO SUELDO LIQ. A BRUTO'!J36 -> 24031.984
B15: 1% REFORMA | C15: ='CALCULO SUELDO LIQ. A BRUTO'!J37 -> 6905.7427
A16: TOTAL EMPLEADOR | C16: =SUM(C12:C15) -> 62842.258
A18: COSTO TOTAL IMPOSICIONES | C18: =SUM(C10+C16) -> 183416.53

Sheet COSTO EMPRESA
A2: Costos sueldos empresa | F2: Costos sueldos empresa con sueldo minimo
B3: Sueldo liquido | C3: Imposiciones | D3: costo total | G3: Sueldo liquido | H3: Imposiciones | I3: costo total | J3: Diferencia
A4: Patron de embarcacion | B4: 1800000 | C4: 463414 | D4: =SUM(B4:C4) -> 2263414 | F4: Patron de embarcacion | G4: 660000 | H4: 161392 | I4: =SUM(G4:H4) -> 821392 | J4: =B4-G4 -> 1140000
A5: Motorista | B5: 1600000 | C5: 392123 | D5: =SUM(B5:C5) -> 1992123 | F5: Motorista | G5: 660000 | H5: 161392 | I5: =SUM(G5:H5) -> 821392 | J5: =B5-G5 -> 940000
A6: Supervisor | B6: 1600000 | C6: 392123 | D6: =SUM(B6:C6) -> 1992123 | F6: Supervisor | G6: 660000 | H6: 161392 | I6: =SUM(G6:H6) -> 821392 | J6: =B6-G6 -> 940000
A7: Administrador | B7: 1600000 | C7: 392123 | D7: =SUM(B7:C7) -> 1992123 | F7: Administrador | G7: 660000 | H7: 161392 | I7: =SUM(G7:H7) -> 821392 | J7: =B7-G7 -> 940000
A8: Tripulante | B8: 1400000 | C8: 356477 | D8: =SUM(B8:C8) -> 1756477 | F8: Tripulante | G8: 660000 | H8: 161392 | I8: =SUM(G8:H8) -> 821392 | J8: =B8-G8 -> 740000
A9: Operario 1 | B9: 1400000 | C9: 356477 | D9: =SUM(B9:C9) -> 1756477 | F9: Operario 1 | G9: 660000 | H9: 161392 | I9: =SUM(G9:H9) -> 821392 | J9: =B9-G9 -> 740000
A10: Operario 2 | B10: 1400000 | C10: 356477 | D10: =SUM(B10:C10) -> 1756477 | F10: Operario 2 | G10: 660000 | H10: 161392 | I10: =SUM(G10:H10) -> 821392 | J10: =B10-G10 -> 740000
A11: Operario 3 | B11: 1400000 | C11: 356477 | D11: =SUM(B11:C11) -> 1756477 | F11: Operario 3 | G11: 660000 | H11: 161392 | I11: =SUM(G11:H11) -> 821392 | J11: =B11-G11 -> 740000
A12: Total | B12: =SUM(B4:B11) -> 12200000 | C12: =SUM(C4:C11) -> 3065691 | D12: =SUM(D4:D11) -> 15265691 | F12: Total | G12: =SUM(G4:G11) -> 5280000 | H12: =SUM(H4:H11) -> 1291136 | I12: =SUM(I4:I11) -> 6571136 | J12: =SUM(J4:J11) -> 6920000 | K12: =I12+J12 -> 13491136
A15: Costos operativos | F15: Gastos Varios
A16: Embarcacion | B16: 13000000 | F16: Prevencionista | G16: 280000
A17: Diesel | B17: 6000000 | F17: Contabilidad | G17: 113400
A18: Viveres | B18: 1000000 | F18: Varios | G18: 100000
A19: Implementos seguridad | B19: 700000 | F19: Total | G19: =SUM(G16:G18) -> 493400
A20: Traslado | B20: 210000
A21: Total | B21: =SUM(B16:B20) -> 20910000

Sheet Hoja2
A3: Costos Sueldos | C3: ='COSTO EMPRESA'!D12 -> 15265691 | D3: (sueldos + Imposiciones)
A5: Costos operativos | C5: ='COSTO EMPRESA'!B21 -> 20910000 | D5: (Embarcación + Diesel+ viveres + traslado+ implementos de seguridad)
A7: Gastos Varios | C7: ='COSTO EMPRESA'!G19 -> 493400
A9: Total operacional | C9: =SUM(C3:C7) -> 36669091
A11: Imprevistos 3% | C11: =C9*3% -> 1100072.7
A13: Margen Utilidad 20% | C13: =C9*20% -> 7333818.2
A15: Total | C15: =C9+C11+C13 -> 45102982
